[2025-06-05T23:34:14.788-0300] {taskinstance.py:1103} INFO - Dependencies all met for dep_context=non-requeueable deps ti=<TaskInstance: test1.get_info scheduled__2025-06-05T02:28:40.519682+00:00 [queued]>
[2025-06-05T23:34:14.791-0300] {taskinstance.py:1103} INFO - Dependencies all met for dep_context=requeueable deps ti=<TaskInstance: test1.get_info scheduled__2025-06-05T02:28:40.519682+00:00 [queued]>
[2025-06-05T23:34:14.791-0300] {taskinstance.py:1308} INFO - Starting attempt 2 of 2
[2025-06-05T23:34:14.894-0300] {taskinstance.py:1327} INFO - Executing <Task(PythonOperator): get_info> on 2025-06-05 02:28:40.519682+00:00
[2025-06-05T23:34:14.904-0300] {standard_task_runner.py:57} INFO - Started process 38258 to run task
[2025-06-05T23:34:14.910-0300] {standard_task_runner.py:84} INFO - Running: ['airflow', 'tasks', 'run', 'test1', 'get_info', 'scheduled__2025-06-05T02:28:40.519682+00:00', '--job-id', '8', '--raw', '--subdir', 'DAGS_FOLDER/test.py', '--cfg-path', '/tmp/tmpm02c2vv5']
[2025-06-05T23:34:14.911-0300] {standard_task_runner.py:85} INFO - Job 8: Subtask get_info
[2025-06-05T23:34:15.033-0300] {task_command.py:410} INFO - Running <TaskInstance: test1.get_info scheduled__2025-06-05T02:28:40.519682+00:00 [running]> on host alex-MS-7D46
[2025-06-05T23:34:15.337-0300] {taskinstance.py:1545} INFO - Exporting env vars: AIRFLOW_CTX_DAG_OWNER='airflow' AIRFLOW_CTX_DAG_ID='test1' AIRFLOW_CTX_TASK_ID='get_info' AIRFLOW_CTX_EXECUTION_DATE='2025-06-05T02:28:40.519682+00:00' AIRFLOW_CTX_TRY_NUMBER='2' AIRFLOW_CTX_DAG_RUN_ID='scheduled__2025-06-05T02:28:40.519682+00:00'
[2025-06-05T23:34:15.343-0300] {taskinstance.py:1824} ERROR - Task failed with exception
Traceback (most recent call last):
  File "/home/alex/mlopszoomcamp/lib/python3.10/site-packages/airflow/operators/python.py", line 181, in execute
    return_value = self.execute_callable()
  File "/home/alex/mlopszoomcamp/lib/python3.10/site-packages/airflow/operators/python.py", line 198, in execute_callable
    return self.python_callable(*self.op_args, **self.op_kwargs)
  File "/home/alex/Homeworks/HW3/dags/test.py", line 34, in get_info
    df = pd.read_parquet("data/yellow_tripdata_2023-03.parquet")
  File "/home/alex/mlopszoomcamp/lib/python3.10/site-packages/pandas/io/parquet.py", line 669, in read_parquet
    return impl.read(
  File "/home/alex/mlopszoomcamp/lib/python3.10/site-packages/pandas/io/parquet.py", line 258, in read
    path_or_handle, handles, filesystem = _get_path_or_handle(
  File "/home/alex/mlopszoomcamp/lib/python3.10/site-packages/pandas/io/parquet.py", line 141, in _get_path_or_handle
    handles = get_handle(
  File "/home/alex/mlopszoomcamp/lib/python3.10/site-packages/pandas/io/common.py", line 882, in get_handle
    handle = open(handle, ioargs.mode)
FileNotFoundError: [Errno 2] No such file or directory: 'data/yellow_tripdata_2023-03.parquet'
[2025-06-05T23:34:15.346-0300] {taskinstance.py:1345} INFO - Marking task as FAILED. dag_id=test1, task_id=get_info, execution_date=20250605T022840, start_date=20250606T023414, end_date=20250606T023415
[2025-06-05T23:34:15.452-0300] {standard_task_runner.py:104} ERROR - Failed to execute job 8 for task get_info ([Errno 2] No such file or directory: 'data/yellow_tripdata_2023-03.parquet'; 38258)
[2025-06-05T23:34:15.482-0300] {local_task_job_runner.py:225} INFO - Task exited with return code 1
[2025-06-05T23:34:15.504-0300] {taskinstance.py:2653} INFO - 0 downstream tasks scheduled from follow-on schedule check
