[2025-06-06T23:04:16.466-0300] {taskinstance.py:1103} INFO - Dependencies all met for dep_context=non-requeueable deps ti=<TaskInstance: taxi_pipeline.prepare_data manual__2025-06-07T02:02:02.318606+00:00 [queued]>
[2025-06-06T23:04:16.469-0300] {taskinstance.py:1103} INFO - Dependencies all met for dep_context=requeueable deps ti=<TaskInstance: taxi_pipeline.prepare_data manual__2025-06-07T02:02:02.318606+00:00 [queued]>
[2025-06-06T23:04:16.469-0300] {taskinstance.py:1308} INFO - Starting attempt 1 of 2
[2025-06-06T23:04:16.586-0300] {taskinstance.py:1327} INFO - Executing <Task(PythonOperator): prepare_data> on 2025-06-07 02:02:02.318606+00:00
[2025-06-06T23:04:16.601-0300] {standard_task_runner.py:57} INFO - Started process 62854 to run task
[2025-06-06T23:04:16.607-0300] {standard_task_runner.py:84} INFO - Running: ['airflow', 'tasks', 'run', 'taxi_pipeline', 'prepare_data', 'manual__2025-06-07T02:02:02.318606+00:00', '--job-id', '33', '--raw', '--subdir', 'DAGS_FOLDER/taxi_dag.py', '--cfg-path', '/tmp/tmpyo4xdpzx']
[2025-06-06T23:04:16.608-0300] {standard_task_runner.py:85} INFO - Job 33: Subtask prepare_data
[2025-06-06T23:04:16.750-0300] {task_command.py:410} INFO - Running <TaskInstance: taxi_pipeline.prepare_data manual__2025-06-07T02:02:02.318606+00:00 [running]> on host alex-MS-7D46
[2025-06-06T23:04:17.010-0300] {taskinstance.py:1545} INFO - Exporting env vars: AIRFLOW_CTX_DAG_OWNER='airflow' AIRFLOW_CTX_DAG_ID='taxi_pipeline' AIRFLOW_CTX_TASK_ID='prepare_data' AIRFLOW_CTX_EXECUTION_DATE='2025-06-07T02:02:02.318606+00:00' AIRFLOW_CTX_TRY_NUMBER='1' AIRFLOW_CTX_DAG_RUN_ID='manual__2025-06-07T02:02:02.318606+00:00'
[2025-06-06T23:04:28.764-0300] {taskinstance.py:1824} ERROR - Task failed with exception
Traceback (most recent call last):
  File "/home/alex/mlopszoomcamp/lib/python3.10/site-packages/pandas/core/indexes/base.py", line 3805, in get_loc
    return self._engine.get_loc(casted_key)
  File "index.pyx", line 167, in pandas._libs.index.IndexEngine.get_loc
  File "index.pyx", line 196, in pandas._libs.index.IndexEngine.get_loc
  File "pandas/_libs/hashtable_class_helper.pxi", line 7081, in pandas._libs.hashtable.PyObjectHashTable.get_item
  File "pandas/_libs/hashtable_class_helper.pxi", line 7089, in pandas._libs.hashtable.PyObjectHashTable.get_item
KeyError: ('PULocationID', 'DOLocationID')

The above exception was the direct cause of the following exception:

Traceback (most recent call last):
  File "/home/alex/mlopszoomcamp/lib/python3.10/site-packages/airflow/operators/python.py", line 181, in execute
    return_value = self.execute_callable()
  File "/home/alex/mlopszoomcamp/lib/python3.10/site-packages/airflow/operators/python.py", line 198, in execute_callable
    return self.python_callable(*self.op_args, **self.op_kwargs)
  File "/home/alex/Homeworks/HW3/dags/taxi_dag.py", line 89, in prepare_data
    dicts = df['PULocationID', 'DOLocationID'].to_dict(orient='records')
  File "/home/alex/mlopszoomcamp/lib/python3.10/site-packages/pandas/core/frame.py", line 4102, in __getitem__
    indexer = self.columns.get_loc(key)
  File "/home/alex/mlopszoomcamp/lib/python3.10/site-packages/pandas/core/indexes/base.py", line 3812, in get_loc
    raise KeyError(key) from err
KeyError: ('PULocationID', 'DOLocationID')
[2025-06-06T23:04:28.767-0300] {taskinstance.py:1345} INFO - Marking task as UP_FOR_RETRY. dag_id=taxi_pipeline, task_id=prepare_data, execution_date=20250607T020202, start_date=20250607T020416, end_date=20250607T020428
[2025-06-06T23:04:28.904-0300] {standard_task_runner.py:104} ERROR - Failed to execute job 33 for task prepare_data (('PULocationID', 'DOLocationID'); 62854)
[2025-06-06T23:04:29.020-0300] {local_task_job_runner.py:225} INFO - Task exited with return code 1
[2025-06-06T23:04:29.029-0300] {taskinstance.py:2653} INFO - 0 downstream tasks scheduled from follow-on schedule check
