[2025-06-06T23:15:17.215-0300] {taskinstance.py:1103} INFO - Dependencies all met for dep_context=non-requeueable deps ti=<TaskInstance: taxi_pipeline.train_model manual__2025-06-07T02:12:53.084272+00:00 [queued]>
[2025-06-06T23:15:17.218-0300] {taskinstance.py:1103} INFO - Dependencies all met for dep_context=requeueable deps ti=<TaskInstance: taxi_pipeline.train_model manual__2025-06-07T02:12:53.084272+00:00 [queued]>
[2025-06-06T23:15:17.218-0300] {taskinstance.py:1308} INFO - Starting attempt 1 of 2
[2025-06-06T23:15:17.293-0300] {taskinstance.py:1327} INFO - Executing <Task(PythonOperator): train_model> on 2025-06-07 02:12:53.084272+00:00
[2025-06-06T23:15:17.309-0300] {standard_task_runner.py:57} INFO - Started process 63649 to run task
[2025-06-06T23:15:17.314-0300] {standard_task_runner.py:84} INFO - Running: ['airflow', 'tasks', 'run', 'taxi_pipeline', 'train_model', 'manual__2025-06-07T02:12:53.084272+00:00', '--job-id', '43', '--raw', '--subdir', 'DAGS_FOLDER/taxi_dag.py', '--cfg-path', '/tmp/tmpfweiwsoj']
[2025-06-06T23:15:17.315-0300] {standard_task_runner.py:85} INFO - Job 43: Subtask train_model
[2025-06-06T23:15:17.449-0300] {task_command.py:410} INFO - Running <TaskInstance: taxi_pipeline.train_model manual__2025-06-07T02:12:53.084272+00:00 [running]> on host alex-MS-7D46
[2025-06-06T23:15:17.675-0300] {taskinstance.py:1545} INFO - Exporting env vars: AIRFLOW_CTX_DAG_OWNER='airflow' AIRFLOW_CTX_DAG_ID='taxi_pipeline' AIRFLOW_CTX_TASK_ID='train_model' AIRFLOW_CTX_EXECUTION_DATE='2025-06-07T02:12:53.084272+00:00' AIRFLOW_CTX_TRY_NUMBER='1' AIRFLOW_CTX_DAG_RUN_ID='manual__2025-06-07T02:12:53.084272+00:00'
[2025-06-06T23:15:17.677-0300] {logging_mixin.py:150} WARNING - 2025/06/06 23:15:17 WARNING mlflow.utils.autologging_utils: MLflow sklearn autologging is known to be compatible with 0.24.1 <= scikit-learn <= 1.6.1, but the installed version is 1.7.0. If you encounter errors during autologging, try upgrading / downgrading scikit-learn to a compatible version, or try upgrading MLflow.
[2025-06-06T23:15:17.783-0300] {taskinstance.py:1824} ERROR - Task failed with exception
Traceback (most recent call last):
  File "/home/alex/mlopszoomcamp/lib/python3.10/site-packages/airflow/operators/python.py", line 181, in execute
    return_value = self.execute_callable()
  File "/home/alex/mlopszoomcamp/lib/python3.10/site-packages/airflow/operators/python.py", line 198, in execute_callable
    return self.python_callable(*self.op_args, **self.op_kwargs)
  File "/home/alex/Homeworks/HW3/dags/taxi_dag.py", line 102, in train_model
    X_train = sparse.load_npz('/tmp/X.npz')
  File "/home/alex/mlopszoomcamp/lib/python3.10/site-packages/scipy/sparse/_matrix_io.py", line 134, in load_npz
    with np.load(file, **PICKLE_KWARGS) as loaded:
  File "/home/alex/mlopszoomcamp/lib/python3.10/site-packages/numpy/lib/_npyio_impl.py", line 451, in load
    fid = stack.enter_context(open(os.fspath(file), "rb"))
FileNotFoundError: [Errno 2] No such file or directory: '/tmp/X.npz'
[2025-06-06T23:15:17.794-0300] {taskinstance.py:1345} INFO - Marking task as UP_FOR_RETRY. dag_id=taxi_pipeline, task_id=train_model, execution_date=20250607T021253, start_date=20250607T021517, end_date=20250607T021517
[2025-06-06T23:15:17.868-0300] {standard_task_runner.py:104} ERROR - Failed to execute job 43 for task train_model ([Errno 2] No such file or directory: '/tmp/X.npz'; 63649)
[2025-06-06T23:15:17.926-0300] {local_task_job_runner.py:225} INFO - Task exited with return code 1
[2025-06-06T23:15:17.946-0300] {taskinstance.py:2653} INFO - 0 downstream tasks scheduled from follow-on schedule check
