[2025-06-06T21:35:47.269-0300] {taskinstance.py:1103} INFO - Dependencies all met for dep_context=non-requeueable deps ti=<TaskInstance: taxi_pipeline.load_data manual__2025-06-07T00:35:39.111586+00:00 [queued]>
[2025-06-06T21:35:47.273-0300] {taskinstance.py:1103} INFO - Dependencies all met for dep_context=requeueable deps ti=<TaskInstance: taxi_pipeline.load_data manual__2025-06-07T00:35:39.111586+00:00 [queued]>
[2025-06-06T21:35:47.273-0300] {taskinstance.py:1308} INFO - Starting attempt 1 of 2
[2025-06-06T21:35:47.372-0300] {taskinstance.py:1327} INFO - Executing <Task(PythonOperator): load_data> on 2025-06-07 00:35:39.111586+00:00
[2025-06-06T21:35:47.381-0300] {standard_task_runner.py:57} INFO - Started process 51906 to run task
[2025-06-06T21:35:47.388-0300] {standard_task_runner.py:84} INFO - Running: ['airflow', 'tasks', 'run', 'taxi_pipeline', 'load_data', 'manual__2025-06-07T00:35:39.111586+00:00', '--job-id', '15', '--raw', '--subdir', 'DAGS_FOLDER/taxi_dag.py', '--cfg-path', '/tmp/tmpixvsfhny']
[2025-06-06T21:35:47.388-0300] {standard_task_runner.py:85} INFO - Job 15: Subtask load_data
[2025-06-06T21:35:47.538-0300] {task_command.py:410} INFO - Running <TaskInstance: taxi_pipeline.load_data manual__2025-06-07T00:35:39.111586+00:00 [running]> on host alex-MS-7D46
[2025-06-06T21:35:47.946-0300] {taskinstance.py:1545} INFO - Exporting env vars: AIRFLOW_CTX_DAG_OWNER='airflow' AIRFLOW_CTX_DAG_ID='taxi_pipeline' AIRFLOW_CTX_TASK_ID='load_data' AIRFLOW_CTX_EXECUTION_DATE='2025-06-07T00:35:39.111586+00:00' AIRFLOW_CTX_TRY_NUMBER='1' AIRFLOW_CTX_DAG_RUN_ID='manual__2025-06-07T00:35:39.111586+00:00'
[2025-06-06T21:35:48.143-0300] {logging_mixin.py:150} INFO - The dataset contain 3403766 rows and 19 columns.
[2025-06-06T21:35:48.146-0300] {logging_mixin.py:150} WARNING - /home/alex/Homeworks/HW3/dags/taxi_dag.py:44 UserWarning: pandas only supports SQLAlchemy connectable (engine/connection) or database string URI or sqlite3 DBAPI2 connection. Other DBAPI2 objects are not tested. Please consider using SQLAlchemy.
[2025-06-06T21:35:48.169-0300] {taskinstance.py:1824} ERROR - Task failed with exception
Traceback (most recent call last):
  File "/home/alex/mlopszoomcamp/lib/python3.10/site-packages/airflow/operators/python.py", line 181, in execute
    return_value = self.execute_callable()
  File "/home/alex/mlopszoomcamp/lib/python3.10/site-packages/airflow/operators/python.py", line 198, in execute_callable
    return self.python_callable(*self.op_args, **self.op_kwargs)
  File "/home/alex/Homeworks/HW3/dags/taxi_dag.py", line 44, in load_data
    df.to_sql('yellow_march23', engine, if_exists='replace', index=False)
  File "/home/alex/mlopszoomcamp/lib/python3.10/site-packages/pandas/util/_decorators.py", line 333, in wrapper
    return func(*args, **kwargs)
  File "/home/alex/mlopszoomcamp/lib/python3.10/site-packages/pandas/core/generic.py", line 3106, in to_sql
    return sql.to_sql(
  File "/home/alex/mlopszoomcamp/lib/python3.10/site-packages/pandas/io/sql.py", line 844, in to_sql
    return pandas_sql.to_sql(
  File "/home/alex/mlopszoomcamp/lib/python3.10/site-packages/pandas/io/sql.py", line 2840, in to_sql
    table.create()
  File "/home/alex/mlopszoomcamp/lib/python3.10/site-packages/pandas/io/sql.py", line 986, in create
    if self.exists():
  File "/home/alex/mlopszoomcamp/lib/python3.10/site-packages/pandas/io/sql.py", line 972, in exists
    return self.pd_sql.has_table(self.name, self.schema)
  File "/home/alex/mlopszoomcamp/lib/python3.10/site-packages/pandas/io/sql.py", line 2855, in has_table
    return len(self.execute(query, [name]).fetchall()) > 0
  File "/home/alex/mlopszoomcamp/lib/python3.10/site-packages/pandas/io/sql.py", line 2662, in execute
    cur = self.con.cursor()
AttributeError: 'Engine' object has no attribute 'cursor'
[2025-06-06T21:35:48.173-0300] {taskinstance.py:1345} INFO - Marking task as UP_FOR_RETRY. dag_id=taxi_pipeline, task_id=load_data, execution_date=20250607T003539, start_date=20250607T003547, end_date=20250607T003548
[2025-06-06T21:35:48.255-0300] {standard_task_runner.py:104} ERROR - Failed to execute job 15 for task load_data ('Engine' object has no attribute 'cursor'; 51906)
[2025-06-06T21:35:48.322-0300] {local_task_job_runner.py:225} INFO - Task exited with return code 1
[2025-06-06T21:35:48.334-0300] {taskinstance.py:2653} INFO - 0 downstream tasks scheduled from follow-on schedule check
