[2025-06-06T23:11:59.237-0300] {taskinstance.py:1103} INFO - Dependencies all met for dep_context=non-requeueable deps ti=<TaskInstance: taxi_pipeline.train_model manual__2025-06-07T02:02:02.318606+00:00 [queued]>
[2025-06-06T23:11:59.240-0300] {taskinstance.py:1103} INFO - Dependencies all met for dep_context=requeueable deps ti=<TaskInstance: taxi_pipeline.train_model manual__2025-06-07T02:02:02.318606+00:00 [queued]>
[2025-06-06T23:11:59.241-0300] {taskinstance.py:1308} INFO - Starting attempt 1 of 2
[2025-06-06T23:11:59.345-0300] {taskinstance.py:1327} INFO - Executing <Task(PythonOperator): train_model> on 2025-06-07 02:02:02.318606+00:00
[2025-06-06T23:11:59.360-0300] {standard_task_runner.py:57} INFO - Started process 63434 to run task
[2025-06-06T23:11:59.365-0300] {standard_task_runner.py:84} INFO - Running: ['airflow', 'tasks', 'run', 'taxi_pipeline', 'train_model', 'manual__2025-06-07T02:02:02.318606+00:00', '--job-id', '38', '--raw', '--subdir', 'DAGS_FOLDER/taxi_dag.py', '--cfg-path', '/tmp/tmplvw1upyw']
[2025-06-06T23:11:59.366-0300] {standard_task_runner.py:85} INFO - Job 38: Subtask train_model
[2025-06-06T23:11:59.467-0300] {task_command.py:410} INFO - Running <TaskInstance: taxi_pipeline.train_model manual__2025-06-07T02:02:02.318606+00:00 [running]> on host alex-MS-7D46
[2025-06-06T23:11:59.660-0300] {taskinstance.py:1545} INFO - Exporting env vars: AIRFLOW_CTX_DAG_OWNER='airflow' AIRFLOW_CTX_DAG_ID='taxi_pipeline' AIRFLOW_CTX_TASK_ID='train_model' AIRFLOW_CTX_EXECUTION_DATE='2025-06-07T02:02:02.318606+00:00' AIRFLOW_CTX_TRY_NUMBER='1' AIRFLOW_CTX_DAG_RUN_ID='manual__2025-06-07T02:02:02.318606+00:00'
[2025-06-06T23:11:59.666-0300] {logging_mixin.py:150} WARNING - 2025/06/06 23:11:59 WARNING mlflow.utils.autologging_utils: MLflow sklearn autologging is known to be compatible with 0.24.1 <= scikit-learn <= 1.6.1, but the installed version is 1.7.0. If you encounter errors during autologging, try upgrading / downgrading scikit-learn to a compatible version, or try upgrading MLflow.
[2025-06-06T23:11:59.767-0300] {taskinstance.py:1824} ERROR - Task failed with exception
Traceback (most recent call last):
  File "/home/alex/mlopszoomcamp/lib/python3.10/site-packages/airflow/operators/python.py", line 181, in execute
    return_value = self.execute_callable()
  File "/home/alex/mlopszoomcamp/lib/python3.10/site-packages/airflow/operators/python.py", line 198, in execute_callable
    return self.python_callable(*self.op_args, **self.op_kwargs)
  File "/home/alex/Homeworks/HW3/dags/taxi_dag.py", line 102, in train_model
    X_train = sparse.load_npz('/tmp/X.npz')
  File "/home/alex/mlopszoomcamp/lib/python3.10/site-packages/scipy/sparse/_matrix_io.py", line 134, in load_npz
    with np.load(file, **PICKLE_KWARGS) as loaded:
  File "/home/alex/mlopszoomcamp/lib/python3.10/site-packages/numpy/lib/_npyio_impl.py", line 451, in load
    fid = stack.enter_context(open(os.fspath(file), "rb"))
FileNotFoundError: [Errno 2] No such file or directory: '/tmp/X.npz'
[2025-06-06T23:11:59.779-0300] {taskinstance.py:1345} INFO - Marking task as UP_FOR_RETRY. dag_id=taxi_pipeline, task_id=train_model, execution_date=20250607T020202, start_date=20250607T021159, end_date=20250607T021159
[2025-06-06T23:11:59.861-0300] {standard_task_runner.py:104} ERROR - Failed to execute job 38 for task train_model ([Errno 2] No such file or directory: '/tmp/X.npz'; 63434)
[2025-06-06T23:11:59.897-0300] {local_task_job_runner.py:225} INFO - Task exited with return code 1
[2025-06-06T23:11:59.907-0300] {taskinstance.py:2653} INFO - 0 downstream tasks scheduled from follow-on schedule check
